<?xml version="1.0"?>
<robot xmlns:xacro="http://www.ros.org/wiki/xacro" name="charging_robot">

  <!-- Constants for robot dimensions -->
  <xacro:property name="PI" value="3.1415926535897931"/>
  <xacro:property name="base_mass" value="10.0"/>
  <xacro:property name="base_width" value="0.5"/>
  <xacro:property name="base_length" value="0.8"/>
  <xacro:property name="base_height" value="0.2"/>
  <xacro:property name="wheel_radius" value="0.1"/>
  <xacro:property name="wheel_width" value="0.05"/>
  <xacro:property name="arm_base_height" value="0.1"/>
  <xacro:property name="arm_link_length" value="0.4"/>

  <!-- Material macros -->
  <material name="blue"> <color rgba="0 0 0.8 1"/> </material>
  <material name="black"> <color rgba="0 0 0 1"/> </material>
  <material name="white"> <color rgba="1 1 1 1"/> </material>
  <material name="orange"> <color rgba="1 0.5 0 1"/> </material>

  <!-- Dummy root link for some tools -->
  <link name="base_footprint"/>

  <joint name="base_footprint_joint" type="fixed">
    <parent link="base_footprint"/>
    <child link="base_link"/>
    <origin xyz="0 0 ${wheel_radius}" rpy="0 0 0"/>
  </joint>

  <!-- Base Link -->
  <link name="base_link">
    <visual>
      <geometry> <box size="${base_length} ${base_width} ${base_height}"/> </geometry>
      <material name="blue"/>
    </visual>
    <collision>
      <geometry> <box size="${base_length} ${base_width} ${base_height}"/> </geometry>
    </collision>
    <inertial>
      <mass value="${base_mass}"/>
      <origin xyz="0 0 0" rpy="0 0 0"/>
      <inertia ixx="0.2" ixy="0" ixz="0" iyy="0.4" iyz="0" izz="0.5"/>
    </inertial>
  </link>

  <!-- Wheels -->
  <xacro:macro name="wheel" params="prefix side">
    <link name="${prefix}_wheel">
      <visual>
        <origin xyz="0 0 0" rpy="${PI/2} 0 0"/>
        <geometry> <cylinder radius="${wheel_radius}" length="${wheel_width}"/> </geometry>
        <material name="black"/>
      </visual>
      <collision>
        <origin xyz="0 0 0" rpy="${PI/2} 0 0"/>
        <geometry> <cylinder radius="${wheel_radius}" length="${wheel_width}"/> </geometry>
      </collision>
      <inertial>
        <mass value="0.5"/>
        <inertia ixx="0.001" ixy="0" ixz="0" iyy="0.001" iyz="0" izz="0.001"/>
      </inertial>
    </link>

    <joint name="${prefix}_wheel_joint" type="continuous">
      <parent link="base_link"/>
      <child link="${prefix}_wheel"/>
      <origin xyz="0 ${side * (base_width/2 + wheel_width/2)} -0.1" rpy="0 0 0"/>
      <axis xyz="0 1 0"/>
    </joint>
  </xacro:macro>

  <xacro:wheel prefix="left" side="1"/>
  <xacro:wheel prefix="right" side="-1"/>

  <!-- Caster Wheel -->
  <link name="caster">
    <visual>
      <geometry> <sphere radius="${wheel_radius/2}"/> </geometry>
      <material name="black"/>
    </visual>
    <collision>
      <geometry> <sphere radius="${wheel_radius/2}"/> </geometry>
    </collision>
    <inertial>
      <mass value="0.2"/>
      <inertia ixx="0.0001" ixy="0" ixz="0" iyy="0.0001" iyz="0" izz="0.0001"/>
    </inertial>
  </link>

  <joint name="caster_joint" type="fixed">
    <parent link="base_link"/>
    <child link="caster"/>
    <origin xyz="${base_length/2 - wheel_radius/2} 0 -${wheel_radius/2 + 0.1}" rpy="0 0 0"/>
  </joint>

  <!-- Arm Base -->
  <link name="arm_base">
    <visual>
      <geometry> <cylinder radius="0.1" length="${arm_base_height}"/> </geometry>
      <material name="white"/>
    </visual>
    <collision>
      <geometry> <cylinder radius="0.1" length="${arm_base_height}"/> </geometry>
    </collision>
    <inertial>
      <mass value="1.0"/>
      <inertia ixx="0.01" ixy="0" ixz="0" iyy="0.01" iyz="0" izz="0.01"/>
    </inertial>
  </link>

  <joint name="arm_base_joint" type="fixed">
    <parent link="base_link"/>
    <child link="arm_base"/>
    <origin xyz="-0.2 0 ${base_height/2 + arm_base_height/2}" rpy="0 0 0"/>
  </joint>

  <!-- Arm Links -->
  <link name="link1">
    <visual>
      <origin xyz="0 0 ${arm_link_length/2}" rpy="0 0 0"/>
      <geometry> <cylinder radius="0.05" length="${arm_link_length}"/> </geometry>
      <material name="orange"/>
    </visual>
    <collision>
      <origin xyz="0 0 ${arm_link_length/2}" rpy="0 0 0"/>
      <geometry> <cylinder radius="0.05" length="${arm_link_length}"/> </geometry>
    </collision>
    <inertial>
      <mass value="0.5"/>
      <inertia ixx="0.01" ixy="0" ixz="0" iyy="0.01" iyz="0" izz="0.01"/>
    </inertial>
  </link>

  <joint name="joint1" type="revolute">
    <parent link="arm_base"/>
    <child link="link1"/>
    <origin xyz="0 0 ${arm_base_height/2}" rpy="0 0 0"/>
    <axis xyz="0 0 1"/>
    <limit lower="-3.14" upper="3.14" effort="10.0" velocity="1.0"/>
  </joint>

  <link name="link2">
    <visual>
      <origin xyz="0 0 ${arm_link_length/2}" rpy="0 0 0"/>
      <geometry> <cylinder radius="0.04" length="${arm_link_length}"/> </geometry>
      <material name="white"/>
    </visual>
    <collision>
      <origin xyz="0 0 ${arm_link_length/2}" rpy="0 0 0"/>
      <geometry> <cylinder radius="0.04" length="${arm_link_length}"/> </geometry>
    </collision>
    <inertial>
      <mass value="0.3"/>
      <inertia ixx="0.01" ixy="0" ixz="0" iyy="0.01" iyz="0" izz="0.01"/>
    </inertial>
  </link>

  <joint name="joint2" type="revolute">
    <parent link="link1"/>
    <child link="link2"/>
    <origin xyz="0 0 ${arm_link_length}" rpy="0 0 0"/>
    <axis xyz="0 1 0"/>
    <limit lower="-1.57" upper="1.57" effort="10.0" velocity="1.0"/>
  </joint>

  <!-- Charging Gun (End Effector) -->
  <link name="charging_gun">
    <visual>
      <origin xyz="0 0 0.05" rpy="0 0 0"/>
      <geometry> <cylinder radius="0.03" length="0.1"/> </geometry>
      <material name="black"/>
    </visual>
    <collision>
      <origin xyz="0 0 0.05" rpy="0 0 0"/>
      <geometry> <cylinder radius="0.03" length="0.1"/> </geometry>
    </collision>
    <inertial>
      <mass value="0.1"/>
      <inertia ixx="0.001" ixy="0" ixz="0" iyy="0.001" iyz="0" izz="0.001"/>
    </inertial>
  </link>

  <joint name="joint3" type="revolute">
    <parent link="link2"/>
    <child link="charging_gun"/>
    <origin xyz="0 0 ${arm_link_length}" rpy="0 0 0"/>
    <axis xyz="0 1 0"/>
    <limit lower="-1.57" upper="1.57" effort="5.0" velocity="1.0"/>
  </joint>

  <!-- Camera for Detection -->
  <link name="camera_link">
    <visual>
      <geometry> <box size="0.05 0.05 0.05"/> </geometry>
      <material name="black"/>
    </visual>
  </link>

  <joint name="camera_joint" type="fixed">
    <parent link="charging_gun"/>
    <child link="camera_link"/>
    <origin xyz="0 0 0.1" rpy="0 -${PI/2} 0"/>
  </joint>

  <!-- LIDAR Sensor -->
  <link name="lidar_link">
    <visual>
      <geometry> <cylinder radius="0.05" length="0.05"/> </geometry>
      <material name="orange"/>
    </visual>
  </link>

  <joint name="lidar_joint" type="fixed">
    <parent link="base_link"/>
    <child link="lidar_link"/>
    <origin xyz="${base_length/2 - 0.1} 0 ${base_height/2 + 0.025}" rpy="0 0 0"/>
  </joint>

  <!-- Gazebo plugins -->
  <gazebo>
    <plugin name="gazebo_ros_diff_drive" filename="libgazebo_ros_diff_drive.so">
      <left_joint>left_wheel_joint</left_joint>
      <right_joint>right_wheel_joint</right_joint>
      <wheel_separation>${base_width + wheel_width}</wheel_separation>
      <wheel_diameter>${2 * wheel_radius}</wheel_diameter>
      <publish_odom>true</publish_odom>
      <publish_odom_tf>true</publish_odom_tf>
      <publish_wheel_tf>true</publish_wheel_tf>
      <odometry_frame>odom</odometry_frame>
      <robot_base_frame>base_footprint</robot_base_frame>
    </plugin>
  </gazebo>

  <gazebo reference="camera_link">
    <sensor type="camera" name="camera">
      <update_rate>15.0</update_rate>
      <camera name="head">
        <horizontal_fov>1.3962634</horizontal_fov>
        <image>
          <width>640</width>
          <height>480</height>
          <format>R8G8B8</format>
        </image>
        <clip> <near>0.02</near> <far>300</far> </clip>
      </camera>
      <plugin name="camera_controller" filename="libgazebo_ros_camera.so">
        <ros>
          <namespace>camera</namespace>
        </ros>
        <frame_name>camera_link</frame_name>
      </plugin>
    </sensor>
  </gazebo>

  <gazebo reference="lidar_link">
    <sensor type="ray" name="lidar">
      <pose>0 0 0 0 0 0</pose>
      <visualize>true</visualize>
      <update_rate>10</update_rate>
      <ray>
        <scan>
          <horizontal>
            <samples>360</samples>
            <resolution>1</resolution>
            <min_angle>-3.14</min_angle>
            <max_angle>3.14</max_angle>
          </horizontal>
        </scan>
        <range>
          <min>0.3</min>
          <max>12.0</max>
          <resolution>0.01</resolution>
        </range>
      </ray>
      <plugin name="lidar_controller" filename="libgazebo_ros_ray_sensor.so">
        <ros>
          <remapping>~/out:=scan</remapping>
        </ros>
        <output_type>sensor_msgs/LaserScan</output_type>
        <frame_name>lidar_link</frame_name>
      </plugin>
    </sensor>
  </gazebo>

  <!-- ros2_control -->
  <ros2_control name="GazeboSystem" type="system">
    <hardware>
      <plugin>gazebo_ros2_control/GazeboSystem</plugin>
    </hardware>
    <joint name="joint1">
      <command_interface name="position"/>
      <state_interface name="position"/>
      <state_interface name="velocity"/>
    </joint>
    <joint name="joint2">
      <command_interface name="position"/>
      <state_interface name="position"/>
      <state_interface name="velocity"/>
    </joint>
    <joint name="joint3">
      <command_interface name="position"/>
      <state_interface name="position"/>
      <state_interface name="velocity"/>
    </joint>
  </ros2_control>

  <gazebo>
    <plugin name="gazebo_ros2_control" filename="libgazebo_ros2_control.so">
      <parameters>$(find charge_port)/config/controllers/arm_controllers.yaml</parameters>
    </plugin>
  </gazebo>

</robot>
